In the `getServerSideProps` function, wrap the asynchronous operation in a `try...catch` block. This will allow you to catch any errors that might occur during the asynchronous operation.

```javascript
// bug.js
export async function getServerSideProps(context) {
  try {
    const response = await fetch('https://api.example.com/data'); // Simulate an API call that might fail
    if (!response.ok) {
      throw new Error(`Failed to fetch data: ${response.status}`);
    }
    const data = await response.json();
    return { props: { data } };
  } catch (error) {
    console.error('Error fetching data:', error);
    return {
      props: {
        error: 'An unexpected error occurred. Please try again later.'
      }
    };
  }
}

// bugSolution.js
export default function Home({ data, error }) {
  if (error) {
    return <div>{error}</div>;
  }
  return (
    <div>
      {/* Render your content here using the data */}
      <h1>Hello World</h1>
    </div>
  );
}
```
By implementing this `try...catch` block, the application will gracefully handle errors during the data fetching process, providing a better user experience and aiding in debugging.